<?xml version="1.0"?>
<robot name="two_link_arm">

  <material name="gray">
    <color rgba="0.7 0.7 0.7 1.0"/>
  </material>
  <material name="purple">
    <color rgba="0.52 0.43 1.0 1.0"/>
  </material>
  <material name="white">
    <color rgba="1.0 1.0 1.0 1.0"/>
  </material>

  <link name="world"/>

  <link name="base_link">
    <inertial>
      <origin xyz="0 0 0"/>
      <mass value="2.0"/>
      <inertia ixx="0.02" ixy="0.0" ixz="0.0" iyy="0.02" iyz="0.0" izz="0.02"/>
    </inertial>
    <visual>
      <origin xyz="0 0 0.05"/>
      <geometry><box size="0.2 0.2 0.1"/></geometry>
      <material name="gray"/>
    </visual>
    <collision>
      <origin xyz="0 0 0.05"/>
      <geometry><box size="0.2 0.2 0.1"/></geometry>
    </collision>
  </link>

  <joint name="world_to_base" type="fixed">
    <parent link="world"/>
    <child link="base_link"/>
    <origin xyz="0 0 0" rpy="0 0 0"/>
  </joint>

  <link name="link1">
    <inertial>
      <origin xyz="0.25 0 0"/>
      <mass value="1.0"/>
      <inertia ixx="0.005" ixy="0.0" ixz="0.0" iyy="0.03" iyz="0.0" izz="0.03"/>
    </inertial>
    <visual>
      <origin xyz="0.25 0 0"/>
      <geometry><box size="0.5 0.05 0.05"/></geometry>
      <material name="white"/>
    </visual>
    <collision>
      <origin xyz="0.25 0 0"/>
      <geometry><box size="0.5 0.05 0.05"/></geometry>
    </collision>
  </link>

  <link name="link2">
    <inertial>
      <origin xyz="0.2 0 0"/>
      <mass value="0.8"/>
      <inertia ixx="0.004" ixy="0.0" ixz="0.0" iyy="0.02" iyz="0.0" izz="0.02"/>
    </inertial>
    <visual>
      <origin xyz="0.2 0 0"/>
      <geometry><box size="0.4 0.04 0.04"/></geometry>
      <material name="purple"/>
    </visual>
    <collision>
      <origin xyz="0.2 0 0"/>
      <geometry><box size="0.4 0.04 0.04"/></geometry>
    </collision>
  </link>

  <joint name="joint1" type="revolute">
    <parent link="base_link"/>
    <child link="link1"/>
    <origin xyz="0 0 0.1" rpy="0 0 0"/>
    <axis xyz="0 0 1"/>
    <limit lower="-1.57" upper="1.57" effort="20.0" velocity="1.0"/>
    <dynamics damping="0.2" friction="0.05"/>
  </joint>

  <joint name="joint2" type="revolute">
    <parent link="link1"/>
    <child link="link2"/>
    <origin xyz="0.5 0 0" rpy="0 0 0"/>
    <axis xyz="0 0 1"/>
    <limit lower="-1.57" upper="1.57" effort="20.0" velocity="1.0"/>
    <dynamics damping="0.2" friction="0.05"/>
  </joint>

  <link name="ee_link"/>

  <joint name="ee_fixed_joint" type="fixed">
    <parent link="link2"/>
    <child link="ee_link"/>
    <origin xyz="0.4 0 0" rpy="0 0 0"/>
  </joint>

  <ros2_control name="GazeboSystem" type="system">
    <hardware>
      <plugin>gz_ros2_control/GazeboSimSystem</plugin>
    </hardware>
    <joint name="joint1">
      <command_interface name="position"/>
      <state_interface name="position"/>
      <state_interface name="velocity"/>
    </joint>
    <joint name="joint2">
      <command_interface name="position"/>
      <state_interface name="position"/>
      <state_interface name="velocity"/>
    </joint>
  </ros2_control>

  <gazebo>
    <plugin name="gz_ros2_control::GazeboSimROS2ControlPlugin" filename="libgz_ros2_control-system.so">
      <parameters>$(find robot_sim_pkg)/config/controllers.yaml</parameters>
    </plugin>
  </gazebo>


</robot>
